<?xml version="1.0" ?>
<!-- =================================================================================== -->
<!-- |    This document was autogenerated by xacro from /home/unity/colcon_ws/install/diffbot_description/share/diffbot_description/robots/diffbot.urdf.xacro | -->
<!-- |    EDITING THIS FILE BY HAND IS NOT RECOMMENDED                                 | -->
<!-- =================================================================================== -->
<!-- Basic differential drive mobile base -->
<robot name="diffbot">
  <material name="gray">
    <color rgba="0.5 0.5 0.5 0.2"/>
  </material>
  <material name="ball">
    <color rgba="0.5 0.5 0.5 0.2"/>
  </material>
  <material name="white">
    <color rgba="1.0 1.0 1.0 1.0"/>
  </material>
  <physics_material name="wheel">
    <friction dynamic="1.0" static="1.0"/>
  </physics_material>
  <physics_material name="ball">
    <friction dynamic="0.0" static="0.0"/>
  </physics_material>
  <link name="base_link">
    <inertial>
      <origin rpy="0 0 0" xyz="0 0 0"/>
      <mass value="0.01"/>
      <inertia ixx="0.0001" ixy="0.0" ixz="0.0" iyy="0.0001" iyz="0.0" izz="0.0001"/>
    </inertial>
  </link>
  <joint name="body_joint" type="fixed">
    <parent link="base_link"/>
    <child link="body_link"/>
    <origin rpy="0 0 0" xyz="-0.7 0 0.7"/>
  </joint>
  <link name="body_link">
    <inertial>
      <origin rpy="0 0 0" xyz="0 0 0"/>
      <mass value="1.0"/>
      <inertia ixx="0.001" ixy="0.0" ixz="0.0" iyy="0.001" iyz="0.0" izz="0.001"/>
    </inertial>
    <visual>
      <origin rpy="0 0 0" xyz="0 0 0"/>
      <geometry>
        <box size="2.4 1.8 0.6"/>
      </geometry>
      <material name="gray"/>
    </visual>
    <collision>
      <origin rpy="0 0 0" xyz="0 0 0"/>
      <geometry>
        <box size="2.4 1.8 0.6"/>
      </geometry>
    </collision>
  </link>
  <joint name="left_wheel_joint" type="continuous">
    <axis xyz="0 0 1"/>
    <parent link="body_link"/>
    <child link="left_wheel_link"/>
    <origin rpy="-1.5707963267948966 0 0" xyz="0.7 1 -0.2"/>
    <unity_drive_api damping="30000" force_limit="1000000" stiffness="0"/>
  </joint>
  <link name="left_wheel_link">
    <inertial>
      <origin rpy="0 0 0" xyz="0 0 0"/>
      <mass value="0.1"/>
      <inertia ixx="0.0001" ixy="0.0" ixz="0.0" iyy="0.0001" iyz="0.0" izz="0.0001"/>
    </inertial>
    <visual>
      <geometry>
        <cylinder length="0.2" radius="0.5"/>
      </geometry>
      <material name="gray"/>
    </visual>
    <collision>
      <geometry>
        <cylinder length="0.2" radius="0.5"/>
      </geometry>
      <physics_material name="wheel"/>
    </collision>
  </link>
  <joint name="right_wheel_joint" type="continuous">
    <axis xyz="0 0 1"/>
    <parent link="body_link"/>
    <child link="right_wheel_link"/>
    <origin rpy="-1.5707963267948966 0 0" xyz="0.7 -1 -0.2"/>
    <unity_drive_api damping="30000" force_limit="1000000" stiffness="0"/>
  </joint>
  <link name="right_wheel_link">
    <inertial>
      <origin rpy="0 0 0" xyz="0 0 0"/>
      <mass value="0.1"/>
      <inertia ixx="0.0001" ixy="0.0" ixz="0.0" iyy="0.0001" iyz="0.0" izz="0.0001"/>
    </inertial>
    <visual>
      <geometry>
        <cylinder length="0.2" radius="0.5"/>
      </geometry>
      <material name="gray"/>
    </visual>
    <collision>
      <geometry>
        <cylinder length="0.2" radius="0.5"/>
      </geometry>
      <physics_material name="wheel"/>
    </collision>
  </link>
  <joint name="ball_joint" type="fixed">
    <parent link="body_link"/>
    <child link="ball_link"/>
    <origin rpy="0 0 0" xyz="-0.7 0 -0.5"/>
  </joint>
  <link name="ball_link">
    <visual>
      <origin rpy="0 0 0" xyz="0 0 0"/>
      <geometry>
        <sphere radius="0.2"/>
      </geometry>
      <material name="ball"/>
    </visual>
    <collision>
      <origin rpy="0 0 0" xyz="0 0 0"/>
      <geometry>
        <sphere radius="0.2"/>
      </geometry>
      <physics_material name="ball"/>
    </collision>
    <inertial>
      <origin rpy="0 0 0" xyz="0 0 0"/>
      <mass value="0.1"/>
      <inertia ixx="0.0001" ixy="0.0" ixz="0.0" iyy="0.0001" iyz="0.0" izz="0.0001"/>
    </inertial>
  </link>
  <joint name="lidar_joint" type="fixed">
    <parent link="body_link"/>
    <child link="lidar_link"/>
    <origin rpy="0 0 0" xyz="0 0 0.2"/>
  </joint>
  <link name="lidar_link">
    <inertial>
      <origin rpy="0 0 0" xyz="0 0 0"/>
      <mass value="0.1"/>
      <inertia ixx="0.0001" ixy="0.0" ixz="0.0" iyy="0.0001" iyz="0.0" izz="0.0001"/>
    </inertial>
    <!-- If visual tag is enable, lidar's ray is blocked. -->
    <!--
    <visual>
      <origin xyz="0 0 0" rpy="0 0 0" />
      <geometry>
        <cylinder radius="0.03" length="0.08" />
      </geometry>
      <material name="white" />
    </visual>
    -->
  </link>
  <joint name="camera_joint" type="fixed">
    <parent link="body_link"/>
    <child link="camera_link"/>
    <origin rpy="0 0 0" xyz="0.05 -0.1 0.1"/>
  </joint>
  <link name="camera_link">
    <inertial>
      <origin rpy="0 0 0" xyz="0 0 0"/>
      <mass value="0.1"/>
      <inertia ixx="0.0001" ixy="0.0" ixz="0.0" iyy="0.0001" iyz="0.0" izz="0.0001"/>
    </inertial>
    <!-- If visual tag is enable, camera's view is blocked. -->
    <!--
    <visual>
      <origin xyz="0 0 0" rpy="0 -1.57 0" />
      <geometry>
        <cylinder radius="0.01" length="0.01" />
      </geometry>
      <material name="white" />
    </visual>
    -->
  </link>
  <joint name="depth_camera_joint" type="fixed">
    <parent link="body_link"/>
    <child link="depth_camera_link"/>
    <origin rpy="0 0 0" xyz="0.05 0.1 0.1"/>
  </joint>
  <link name="depth_camera_link">
    <inertial>
      <origin rpy="0 0 0" xyz="0 0 0"/>
      <mass value="0.1"/>
      <inertia ixx="0.0001" ixy="0.0" ixz="0.0" iyy="0.0001" iyz="0.0" izz="0.0001"/>
    </inertial>
    <!-- If visual tag is enable, camera's view is blocked. -->
    <!--
    <visual>
      <origin xyz="0 0 0" rpy="0 -1.57 0" />
      <geometry>
        <cylinder radius="0.01" length="0.01" />
      </geometry>
      <material name="white" />
    </visual>
    -->
  </link>
  <ros2_control name="diffbot" type="system">
    <hardware>
    </hardware>
    <joint name="left_wheel_joint">
      <command_interface name="velocity">
        <param name="min">-1</param>
        <param name="max">1</param>
      </command_interface>
      <state_interface name="position"/>
      <state_interface name="velocity"/>
      <state_interface name="effort"/>
    </joint>
    <joint name="right_wheel_joint">
      <command_interface name="velocity">
        <param name="min">-1</param>
        <param name="max">1</param>
      </command_interface>
      <state_interface name="position"/>
      <state_interface name="velocity"/>
      <state_interface name="effort"/>
    </joint>
  </ros2_control>
  <!-- =============== Isaac Sim =============== -->
  <unity>
    <sensor name="lidar_link" type="lidar">
      <update_rate>10</update_rate>
      <ray>
        <scan>
          <horizontal>
            <samples>400</samples>
            <resolution>1</resolution>
            <min_angle>-3.1415</min_angle>
            <max_angle>3.1415</max_angle>
          </horizontal>
        </scan>
        <range>
          <min>0.05</min>
          <max>20.0</max>
          <resolution>0.01</resolution>
        </range>
        <noise>
          <type>gaussian</type>
          <mean>0.0</mean>
          <stddev>0.01</stddev>
        </noise>
      </ray>
      <topicName>/lidar/scan</topicName>
      <frameName>lidar_link</frameName>
    </sensor>
    <sensor name="camera_link" type="camera">
      <update_rate>30.0</update_rate>
      <horizontal_fov>1.3962634</horizontal_fov>
      <image>
        <width>800</width>
        <height>600</height>
      </image>
      <clip>
        <near>0.02</near>
        <far>300</far>
      </clip>
      <cameraName>/camera</cameraName>
      <imageTopicName>image_raw</imageTopicName>
      <cameraInfoTopicName>camera_info</cameraInfoTopicName>
      <frameName>camera_link</frameName>
    </sensor>
    <sensor name="depth_camera_link" type="depth_camera">
      <update_rate>10.0</update_rate>
      <horizontal_fov>1.3962634</horizontal_fov>
      <image>
        <width>320</width>
        <height>240</height>
      </image>
      <clip>
        <near>0.02</near>
        <far>300</far>
      </clip>
      <cameraName>/depth_camera</cameraName>
      <imageTopicName>depth_image_raw</imageTopicName>
      <cameraInfoTopicName>depth_camera_info</cameraInfoTopicName>
      <frameName>depth_camera_link</frameName>
    </sensor>
  </unity>
</robot>
